Workbook
Name ACTION: #REF!
Name ACTION: #REF!

Sheet Cover
B2: SYSTEM TEST REPORT DOCUMENT
A4: Project Name | B4: SakuJi JLPT Learning Platform | E4: Creator | F4: Senior QA Automation Engineer
A5: Project Code | B5: SAKUJI-JLPT | E5: Issue Date | F5: 46229
A6: Document Code | B6: ="SAKUJI-JLPT_ST_v3.0" | E6: Version | F6: 3.0
A9: Record of change
A10: Effective Date | B10: Version | C10: Change Item | D10: *A,D,M | E10: Change description | F10: Reference
A11: 46229 | B11: 3.0 | C11: Complete System Test Suite | D11: A | E11: Imported 142 detailed test cases, traceability and execution baseline from SystemTest.md. | F11: SystemTest.md; docs/00-Tong-Quan-He-Thong.md
A12: 46229 | B12: 3.1 | C12: Codex QA | D12: System Test execution | E12: Round 1 recorded in English: 11 Passed, 131 Pending, 0 Failed. Backend 120/120 and frontend 18/18 automated tests passed.

Sheet Test Cases
D1: TEST CASE LIST
B3: Project Name | D3: SakuJi JLPT Learning Platform
B4: Project Code | D4: SAKUJI-JLPT
B5: Test Environment Setup Description | D5: Java 21; Spring Boot 3.3.3; Node.js 24; React 18; MySQL 8.4 target; Chrome/Firefox/Edge; SMTP/OAuth sandbox; Playwright/REST system runner proposed. Current execution baseline used H2 because Docker/MySQL was unavailable.
B8: No | C8: Function Name | D8: Sheet Name | E8: Description | F8: Pre-Condition
B9: 1 | C9: Auth / Public | D9: Auth_Public | E9: Authentication, public pages, session and route guards | F9: Environment and actor fixtures prepared; dependent workflows completed.
B10: 2 | C10: Student | D10: Student | E10: Student learning, profile, assessment, support and notification | F10: Environment and actor fixtures prepared; dependent workflows completed.
B11: 3 | C11: Staff | D11: Staff | E11: Staff dashboard, authoring, support, broadcast and grading | F11: Environment and actor fixtures prepared; dependent workflows completed.
B12: 4 | C12: Manager | D12: Manager | E12: StaffManager review, publish, restore and coordination | F12: Environment and actor fixtures prepared; dependent workflows completed.
B13: 5 | C13: Admin | D13: Admin | E13: Admin dashboard, users, settings, audit and notification rules | F13: Environment and actor fixtures prepared; dependent workflows completed.
B14: 6 | C14: CrossRole / Security | D14: CrossRole_Security | E14: Cross-role authorization, security, reliability, UI and database | F14: Environment and actor fixtures prepared; dependent workflows completed.

Sheet Test Statistics
B1: TEST STATISTICS
B3: Project Name | C3: SakuJi JLPT Learning Platform | E3: Creator | G3: Senior QA Automation Engineer
B4: Project Code | C4: SAKUJI-JLPT | E4: Reviewer/Approver | G4: TBD
B5: Document Code | C5: ="SAKUJI-JLPT_Test Report_v3.0" | E5: Issue Date | H5: 46229
B6: Notes | C6: Release scope: all 40 use cases and 142 detailed System Test IDs. Round 1 remains Pending until full-stack/browser execution.
B10: No | C10: Module code | D10: Passed | E10: Failed | F10: Pending | G10: N/A | H10: Number of test cases
B11: 1 | C11: ='Auth_Public'!B2 | D11: ='Auth_Public'!B6 | E11: ='Auth_Public'!C6 | F11: ='Auth_Public'!D6 | G11: ='Auth_Public'!E6 | H11: ='Auth_Public'!B4
B12: 2 | C12: ='Student'!B2 | D12: ='Student'!B6 | E12: ='Student'!C6 | F12: ='Student'!D6 | G12: ='Student'!E6 | H12: ='Student'!B4
B13: 3 | C13: ='Staff'!B2 | D13: ='Staff'!B6 | E13: ='Staff'!C6 | F13: ='Staff'!D6 | G13: ='Staff'!E6 | H13: ='Staff'!B4
B14: 4 | C14: ='Manager'!B2 | D14: ='Manager'!B6 | E14: ='Manager'!C6 | F14: ='Manager'!D6 | G14: ='Manager'!E6 | H14: ='Manager'!B4
B15: 5 | C15: ='Admin'!B2 | D15: ='Admin'!B6 | E15: ='Admin'!C6 | F15: ='Admin'!D6 | G15: ='Admin'!E6 | H15: ='Admin'!B4
B16: 6 | C16: ='CrossRole_Security'!B2 | D16: ='CrossRole_Security'!B6 | E16: ='CrossRole_Security'!C6 | F16: ='CrossRole_Security'!D6 | G16: ='CrossRole_Security'!E6 | H16: ='CrossRole_Security'!B4
C17: Sub total | D17: =SUM(D11:D16) | E17: =SUM(E11:E16) | F17: =SUM(F11:F16) | G17: =SUM(G11:G16) | H17: =SUM(H11:H16)
C19: Test coverage | E19: =(D17+E17)*100/(H17-G17) | F19: %
C20: Test successful coverage | E20: =D17*100/(H17-G17) | F20: %

Sheet Auth_Public
A2: Workflow | B2: Auth_Public | R2: Passed
A3: Test requirement | B3: Authentication, public pages, session and route guards | R3: Failed
A4: Number of TCs | B4: =COUNTA(A12:A1000) | R4: Pending
A5: Testing Round | B5: Passed | C5: Failed | D5: Pending | E5: N/A | R5: N/A
A6: Round 1 | B6: =COUNTIF($F$12:$F$1000,"Passed") | C6: =COUNTIF($F$12:$F$1000,"Failed") | D6: =COUNTIF($F$12:$F$1000,"Pending") | E6: =COUNTIF($F$12:$F$1000,"N/A")
A7: Round 2 | B7: =COUNTIF($I$12:$I$1000,"Passed") | C7: =COUNTIF($I$12:$I$1000,"Failed") | D7: =COUNTIF($I$12:$I$1000,"Pending") | E7: =COUNTIF($I$12:$I$1000,"N/A")
A8: Round 3 | B8: =COUNTIF($L$12:$L$1000,"Passed") | C8: =COUNTIF($L$12:$L$1000,"Failed") | D8: =COUNTIF($L$12:$L$1000,"Pending") | E8: =COUNTIF($L$12:$L$1000,"N/A")
A10: Test Case ID | B10: Test Case Description | C10: Test Case Procedure | D10: Expected Results | E10: Pre-conditions | F10: Round 1 | G10: Test date | H10: Tester | I10: Round 2 | J10: Test date | K10: Tester | L10: Round 3 | M10: Test date | N10: Tester | O10: Note
A11: Scenario: Public
A12: AUTH-001 | B12: [Khách] Landing/menu | C12: 1. Mở `/` 2. kiểm tra logo, menu, CTA 3. đi tới Features/Blog/Login/Register | D12: Trang render không lỗi; menu/CTA điều hướng đúng; không lộ menu protected | E12: App running | F12: Pending | G12: 46229 | H12: Codex QA | I12: Pending | L12: Pending | O12: Test Data: N/A Priority: P1 Type: Smoke, UI ROUND 1 ACTUAL RESULT (26 Jul 2026): PENDING — Frontend unit tests, lint, and production build passed, but no Playwright/Cypress browser runner is configured for this end-to-end UI scenario.
A13: Scenario: Auth
A14: AUTH-002 | B14: [Khách] Register positive | C14: 1. Mở Register 2. nhập hợp lệ 3. submit | D14: API 201/200; Student `pending`; email OTP được gửi; UI chuyển verify | E14: Email chưa tồn tại | F14: Pending | G14: 46229 | H14: Codex QA | I14: Pending | L14: Pending | O14: Test Data: email mới, `PWD-OK`, `JP-TEXT` name Priority: P0 Type: Functional, Integration ROUND 1 ACTUAL RESULT (26 Jul 2026): PENDING — The relevant external provider/file-delivery workflow was not available as a complete System Test environment. Mocked automated checks passed where present.
A15: AUTH-003 | B15: [Khách] Register invalid/boundary | C15: 1. Submit rỗng 2. email sai 3. password dưới/đúng/trên giới hạn 4. name Unicode dài | D15: Client và server cùng chặn; field message rõ; không tạo DB row | E15: None | F15: Pending | G15: 46229 | H15: Codex QA | I15: Pending | L15: Pending | O15: Test Data: invalid/boundary set Priority: P1 Type: Negative, Boundary ROUND 1 ACTUAL RESULT (26 Jul 2026): PENDING — No automated test directly covers every step and expected result of this System Test. Backend 120/120 and frontend 18/18 automated tests passed, but manual/full-stack execution is still required.
A16: AUTH-004 | B16: [Khách] Register duplicate/race | C16: Gửi hai register đồng thời cùng email | D16: Chỉ một account; request còn lại 409/validation; không duplicate | E16: Email đã có | F16: Pending | G16: 46229 | H16: Codex QA | I16: Pending | L16: Pending | O16: Test Data: same email Priority: P0 Type: Concurrent, Database ROUND 1 ACTUAL RESULT (26 Jul 2026): PENDING — The relevant external provider/file-delivery workflow was not available as a complete System Test environment. Mocked automated checks passed where present.
A17: AUTH-005 | B17: [Khách] Verify OTP positive | C17: 1. Mở `/verify-email` 2. nhập OTP 3. submit | D17: `email_verified_at` được set; token không tái sử dụng; có thể login | E17: `U-STU-P`, OTP còn hạn | F17: Pending | G17: 46229 | H17: Codex QA | I17: Pending | L17: Pending | O17: Test Data: OTP đúng 6 số Priority: P0 Type: Functional ROUND 1 ACTUAL RESULT (26 Jul 2026): PENDING — The relevant external provider/file-delivery workflow was not available as a complete System Test environment. Mocked automated checks passed where present.
A18: AUTH-006 | B18: [Khách] Verify/resend negative | C18: 1. Nhập OTP sai, hết hạn, đã dùng 2. resend liên tục | D18: Không verify; thông báo an toàn; rate/expiry được tôn trọng; OTP mới vô hiệu OTP cũ nếu thiết kế | E18: Pending account | F18: Pending | G18: 46229 | H18: Codex QA | I18: Pending | L18: Pending | O18: Test Data: invalid OTP Priority: P1 Type: Negative, Security ROUND 1 ACTUAL RESULT (26 Jul 2026): PENDING — The relevant external provider/file-delivery workflow was not available as a complete System Test environment. Mocked automated checks passed where present.
A19: AUTH-007 | B19: [Mọi role] Login positive | C19: Login lần lượt Student/Staff/Manager/Admin | D19: Token đúng actor/role; redirect `/dashboard`, `/staff`, `/manager`, `/admin` | E19: Account active | F19: Pending | G19: 46229 | H19: Codex QA | I19: Pending | L19: Pending | O19: Test Data: valid credentials Priority: P0 Type: Smoke, Functional ROUND 1 ACTUAL RESULT (26 Jul 2026): PARTIALLY EXECUTED — AuthControllerIntegrationTest passed Student login; Staff, Manager, Admin redirects, and browser behavior were not executed.
A20: AUTH-008 | B20: [Mọi role] Login invalid | C20: 1. Sai password 2. email lạ 3. rỗng 4. SQL/XSS | D20: 401/validation; message không tiết lộ account; không login | E20: Account exists | F20: Pending | G20: 46229 | H20: Codex QA | I20: Pending | L20: Pending | O20: Test Data: invalid set Priority: P0 Type: Negative, Security ROUND 1 ACTUAL RESULT (26 Jul 2026): PARTIALLY EXECUTED — AuthControllerIntegrationTest passed valid and bad-credential cases; empty, SQL/XSS, and all-role UI cases were not executed.
A21: AUTH-009 | B21: [Mọi role] Lock/suspend/deleted | C21: Login | D21: Bị từ chối; không cấp token; lý do phù hợp không lộ dữ liệu nhạy cảm | E21: Account locked/suspended/deleted | F21: Pending | G21: 46229 | H21: Codex QA | I21: Pending | L21: Pending | O21: Test Data: accounts by state Priority: P0 Type: Permission, Security ROUND 1 ACTUAL RESULT (26 Jul 2026): PARTIALLY EXECUTED — AuthenticationServiceTest passed suspended and locked account checks; deleted account and all-role API/UI coverage remain.
A22: Scenario: Staff Auth
A23: AUTH-010 | B23: [Staff] Setup password | C23: 1. Mở setup 2. nhập/confirm password 3. submit | D23: Password hash lưu; token revoked; login Staff thành công | E23: Valid setup token | F23: Pending | G23: 46229 | H23: Codex QA | I23: Pending | L23: Pending | O23: Test Data: `PWD-OK` Priority: P0 Type: Functional ROUND 1 ACTUAL RESULT (26 Jul 2026): PENDING — No automated test directly covers every step and expected result of this System Test. Backend 120/120 and frontend 18/18 automated tests passed, but manual/full-stack execution is still required.
A24: AUTH-011 | B24: [Staff] Temp-password workflow | C24: 1. Login temp 2. thử truy cập Staff page 3. đổi password | D24: Chỉ limited session; buộc đổi; sau đổi temp password hết hiệu lực | E24: Admin issued temp password | F24: Pending | G24: 46229 | H24: Codex QA | I24: Pending | L24: Pending | O24: Test Data: temp + new Priority: P0 Type: Security, Integration ROUND 1 ACTUAL RESULT (26 Jul 2026): PARTIALLY EXECUTED — AuthenticationServiceTest verified limited Staff sessions for temporary passwords; the complete password-change browser workflow remains.
A25: AUTH-012 | B25: [Staff] Forgot request | C25: Submit forgot nhiều lần | D25: Reset request pending duy nhất hợp lệ; Admin thấy request; chống account enumeration | E25: Active Staff | F25: Pending | G25: 46229 | H25: Codex QA | I25: Pending | L25: Pending | O25: Test Data: staff email Priority: P1 Type: Functional, Security ROUND 1 ACTUAL RESULT (26 Jul 2026): PENDING — The relevant external provider/file-delivery workflow was not available as a complete System Test environment. Mocked automated checks passed where present.
A26: Scenario: Auth
A27: AUTH-013 | B27: [Khách] Forgot/reset Student | C27: 1. Request reset 2. dùng token 3. login password mới | D27: Email gửi; password đổi; reset token one-time; phiên cũ xử lý theo policy | E27: Verified Student | F27: Pending | G27: 46229 | H27: Codex QA | I27: Pending | L27: Pending | O27: Test Data: valid token Priority: P0 Type: Functional ROUND 1 ACTUAL RESULT (26 Jul 2026): PENDING — No automated test directly covers every step and expected result of this System Test. Backend 120/120 and frontend 18/18 automated tests passed, but manual/full-stack execution is still required.
A28: AUTH-014 | B28: [Khách] Reset invalid | C28: Submit password mới | D28: Không đổi password; 400/401; audit/log không chứa token/password | E28: Reset token invalid/expired | F28: Pending | G28: 46229 | H28: Codex QA | I28: Pending | L28: Pending | O28: Test Data: expired/tampered token Priority: P1 Type: Negative, Security ROUND 1 ACTUAL RESULT (26 Jul 2026): PENDING — No automated test directly covers every step and expected result of this System Test. Backend 120/120 and frontend 18/18 automated tests passed, but manual/full-stack execution is still required.
A29: AUTH-015 | B29: [Student] Google OAuth | C29: Login Google lần đầu và lần sau | D29: Account link/create đúng; unique provider ID; JWT Student được cấp | E29: OAuth test account | F29: Pending | G29: 46229 | H29: Codex QA | I29: Pending | L29: Pending | O29: Test Data: valid Google token Priority: P1 Type: Integration ROUND 1 ACTUAL RESULT (26 Jul 2026): PENDING — The relevant external provider/file-delivery workflow was not available as a complete System Test environment. Mocked automated checks passed where present.
A30: AUTH-016 | B30: [Khách] Google token attack | C30: Gửi fake token/wrong audience/email collision | D30: 401/409; không takeover/link sai account | E30: None | F30: Pending | G30: 46229 | H30: Codex QA | I30: Pending | L30: Pending | O30: Test Data: forged token Priority: P0 Type: Security ROUND 1 ACTUAL RESULT (26 Jul 2026): PENDING — No automated test directly covers every step and expected result of this System Test. Backend 120/120 and frontend 18/18 automated tests passed, but manual/full-stack execution is still required.
A31: Scenario: Session
A32: AUTH-017 | B32: [Mọi role] Refresh positive | C32: 1. Hết access 2. gọi protected API 3. refresh 4. retry | D32: Access mới hợp lệ; request retry thành công; refresh actor không đổi | E32: Valid refresh token | F32: Pending | G32: 46229 | H32: Codex QA | I32: Pending | L32: Pending | O32: Test Data: valid refresh Priority: P0 Type: Functional ROUND 1 ACTUAL RESULT (26 Jul 2026): PENDING — No automated test directly covers every step and expected result of this System Test. Backend 120/120 and frontend 18/18 automated tests passed, but manual/full-stack execution is still required.
A33: AUTH-018 | B33: [Mọi role] Refresh invalid/replay | C33: Gọi refresh đồng thời/replay | D33: 401; không cấp token; rotation/revocation theo code; không đổi role | E33: Expired/revoked/wrong-signature | F33: Pending | G33: 46229 | H33: Codex QA | I33: Pending | L33: Pending | O33: Test Data: `JWT-X` Priority: P0 Type: Security, Concurrent ROUND 1 ACTUAL RESULT (26 Jul 2026): PENDING — No automated test directly covers every step and expected result of this System Test. Backend 120/120 and frontend 18/18 automated tests passed, but manual/full-stack execution is still required.
A34: AUTH-019 | B34: [Mọi role] Logout | C34: 1. Logout 2. dùng lại access/refresh | D34: Refresh/session bị revoke theo policy; UI xóa session và về Login | E34: Logged in | F34: Pending | G34: 46229 | H34: Codex QA | I34: Pending | L34: Pending | O34: Test Data: tokens Priority: P0 Type: Functional, Security ROUND 1 ACTUAL RESULT (26 Jul 2026): PENDING — No automated test directly covers every step and expected result of this System Test. Backend 120/120 and frontend 18/18 automated tests passed, but manual/full-stack execution is still required.
A35: AUTH-020 | B35: [Mọi role] Timeout | C35: 1. Điều khiển clock qua expiry 2. thao tác UI/API | D35: 401; refresh nếu còn hạn, nếu không thì login; không mất form ngoài thông báo hợp lý | E35: Session gần hết hạn | F35: Pending | G35: 46229 | H35: Codex QA | I35: Pending | L35: Pending | O35: Test Data: expired access/refresh Priority: P0 Type: Security, UI ROUND 1 ACTUAL RESULT (26 Jul 2026): PENDING — Frontend unit tests, lint, and production build passed, but no Playwright/Cypress browser runner is configured for this end-to-end UI scenario.
A36: Scenario: Security
A37: AUTH-021 | B37: [Mọi role] JWT manipulation | C37: 1. Sửa role/sub/expiry 2. đổi alg 3. dùng token actor khác | D37: Tất cả bị 401/403; không truy cập hoặc ghi DB | E37: Any valid token | F37: Pending | G37: 46229 | H37: Codex QA | I37: Pending | L37: Pending | O37: Test Data: tampered tokens Priority: P0 Type: Security ROUND 1 ACTUAL RESULT (26 Jul 2026): PARTIALLY EXECUTED — JwtProviderTest passed access/refresh token validation and invalid-token rejection; the complete claim/algorithm manipulation matrix remains.
A38: Scenario: Route Guard
A39: AUTH-022 | B39: [Khách] Direct protected URL | C39: Mở từng route protected bằng URL | D39: Redirect Login/403; không render dữ liệu protected trước redirect | E39: Logged out | F39: Pending | G39: 46229 | H39: Codex QA | I39: Pending | L39: Pending | O39: Test Data: route inventory Priority: P0 Type: Permission, UI ROUND 1 ACTUAL RESULT (26 Jul 2026): PENDING — Frontend unit tests, lint, and production build passed, but no Playwright/Cypress browser runner is configured for this end-to-end UI scenario.

Sheet Student
A2: Workflow | B2: Student | R2: Passed
A3: Test requirement | B3: Student learning, profile, assessment, support and notification | R3: Failed
A4: Number of TCs | B4: =COUNTA(A12:A1000) | R4: Pending
A5: Testing Round | B5: Passed | C5: Failed | D5: Pending | E5: N/A | R5: N/A
A6: Round 1 | B6: =COUNTIF($F$12:$F$1000,"Passed") | C6: =COUNTIF($F$12:$F$1000,"Failed") | D6: =COUNTIF($F$12:$F$1000,"Pending") | E6: =COUNTIF($F$12:$F$1000,"N/A")
A7: Round 2 | B7: =COUNTIF($I$12:$I$1000,"Passed") | C7: =COUNTIF($I$12:$I$1000,"Failed") | D7: =COUNTIF($I$12:$I$1000,"Pending") | E7: =COUNTIF($I$12:$I$1000,"N/A")
A8: Round 3 | B8: =COUNTIF($L$12:$L$1000,"Passed") | C8: =COUNTIF($L$12:$L$1000,"Failed") | D8: =COUNTIF($L$12:$L$1000,"Pending") | E8: =COUNTIF($L$12:$L$1000,"N/A")
A10: Test Case ID | B10: Test Case Description | C10: Test Case Procedure | D10: Expected Results | E10: Pre-conditions | F10: Round 1 | G10: Test date | H10: Tester | I10: Round 2 | J10: Test date | K10: Tester | L10: Round 3 | M10: Test date | N10: Tester | O10: Note
A11: Scenario: Onboarding
A12: STU-001 | B12: [Student] Save goals | C12: 1. Chọn goal/minutes/skills 2. submit 3. reload | D12: Dữ liệu lưu; dashboard phản ánh; không tạo trùng | E12: `U-STU-A`, chưa onboarding | F12: Pending | G12: 46229 | H12: Codex QA | I12: Pending | L12: Pending | O12: Test Data: N5, 30 phút Priority: P1 Type: Functional, Integration ROUND 1 ACTUAL RESULT (26 Jul 2026): PENDING — No automated test directly covers every step and expected result of this System Test. Backend 120/120 and frontend 18/18 automated tests passed, but manual/full-stack execution is still required.
A13: STU-002 | B13: [Student] Invalid/boundary | C13: 1. Gửi goal sai, minutes 0/âm/rất lớn, skills lạ 2. bypass UI | D13: 400; không cập nhật DB | E13: Logged in | F13: Pending | G13: 46229 | H13: Codex QA | I13: Pending | L13: Pending | O13: Test Data: invalid set Priority: P1 Type: Negative, API ROUND 1 ACTUAL RESULT (26 Jul 2026): PENDING — No automated test directly covers every step and expected result of this System Test. Backend 120/120 and frontend 18/18 automated tests passed, but manual/full-stack execution is still required.
A14: Scenario: Dashboard
A15: STU-003 | B15: [Student] Load summary | C15: 1. Mở `/dashboard` 2. kiểm tra stats và next lesson | D15: Loading→data; số liệu đúng view/query; empty state đúng | E15: Có/không có activity | F15: Pending | G15: 46229 | H15: Codex QA | I15: Pending | L15: Pending | O15: Test Data: seeded activity Priority: P0 Type: Smoke, UI, Database ROUND 1 ACTUAL RESULT (26 Jul 2026): PENDING — Frontend unit tests, lint, and production build passed, but no Playwright/Cypress browser runner is configured for this end-to-end UI scenario.
A16: Scenario: Profile
A17: STU-004 | B17: [Student] View/update | C17: 1. Mở profile 2. sửa name/phone Unicode 3. reload | D17: GET/PUT đúng account; DB update; validation chiều dài/phone | E17: Logged in | F17: Pending | G17: 46229 | H17: Codex QA | I17: Pending | L17: Pending | O17: Test Data: boundary values Priority: P1 Type: Functional ROUND 1 ACTUAL RESULT (26 Jul 2026): PENDING — No automated test directly covers every step and expected result of this System Test. Backend 120/120 and frontend 18/18 automated tests passed, but manual/full-stack execution is still required.
A18: STU-005 | B18: [Student] Avatar upload | C18: 1. Upload ảnh hợp lệ 2. sau đó file xấu/quá lớn/path traversal | D18: Ảnh hợp lệ hiển thị; file xấu 400/415; không thực thi/ghi ngoài storage | E18: Logged in | F18: Pending | G18: 46229 | H18: Codex QA | I18: Pending | L18: Pending | O18: Test Data: image + `FILE-BAD` Priority: P0 Type: Security, Integration ROUND 1 ACTUAL RESULT (26 Jul 2026): PENDING — The relevant external provider/file-delivery workflow was not available as a complete System Test environment. Mocked automated checks passed where present.
A19: STU-006 | B19: [Student] Change password | C19: 1. Sai current 2. mismatch 3. password yếu 4. hợp lệ | D19: Chỉ hợp lệ mới đổi; hash bcrypt; mật khẩu không log/response | E19: Logged in | F19: Pending | G19: 46229 | H19: Codex QA | I19: Pending | L19: Pending | O19: Test Data: password set Priority: P0 Type: Security ROUND 1 ACTUAL RESULT (26 Jul 2026): PENDING — No automated test directly covers every step and expected result of this System Test. Backend 120/120 and frontend 18/18 automated tests passed, but manual/full-stack execution is still required.
A20: STU-007 | B20: [Student] Change email OTP | C20: 1. Request OTP 2. confirm đúng 3. thử sai/hết hạn/email trùng | D20: Email đổi sau OTP; unique giữ nguyên; token one-time; audit phù hợp | E20: Logged in | F20: Pending | G20: 46229 | H20: Codex QA | I20: Pending | L20: Pending | O20: Test Data: email set Priority: P0 Type: Functional, Security ROUND 1 ACTUAL RESULT (26 Jul 2026): PENDING — The relevant external provider/file-delivery workflow was not available as a complete System Test environment. Mocked automated checks passed where present.
A21: Scenario: Learning
A22: STU-008 | B22: [Student] Course/JLPT list | C22: 1. Mở `/courses` 2. chọn level | D22: Danh sách lộ trình đúng; không phụ thuộc bảng `courses`; UI responsive | E22: Published content exists | F22: Pending | G22: 46229 | H22: Codex QA | I22: Pending | L22: Pending | O22: Test Data: N5–N1 Priority: P1 Type: Functional, UI ROUND 1 ACTUAL RESULT (26 Jul 2026): PARTIALLY EXECUTED — CourseServiceTest passed five-level ordering, default-level, missing-user, and progress mapping; browser/responsive checks remain.
A23: Scenario: Lesson
A24: STU-009 | B24: [Student] Lesson detail/progress | C24: 1. Mở `/lessons/:id` 2. hoàn thành | D24: Nội dung/media đúng; progress upsert unique và 100%; next lesson đổi | E24: Published lesson | F24: Pending | G24: 46229 | H24: Codex QA | I24: Pending | L24: Pending | O24: Test Data: valid lesson Priority: P0 Type: Functional, Integration ROUND 1 ACTUAL RESULT (26 Jul 2026): PENDING — No automated test directly covers every step and expected result of this System Test. Backend 120/120 and frontend 18/18 automated tests passed, but manual/full-stack execution is still required.
A25: STU-010 | B25: [Student] Hidden/missing lesson | C25: Direct URL/API | D25: 403/404; không lộ content draft/deleted | E25: Draft/deleted/unknown ID | F25: Pending | G25: 46229 | H25: Codex QA | I25: Pending | L25: Pending | O25: Test Data: IDs Priority: P0 Type: Permission ROUND 1 ACTUAL RESULT (26 Jul 2026): PENDING — No automated test directly covers every step and expected result of this System Test. Backend 120/120 and frontend 18/18 automated tests passed, but manual/full-stack execution is still required.
A26: Scenario: Kana
A27: STU-011 | B27: [Student] List/progress | C27: 1. Mở `/kana` 2. lọc/tương tác 3. đánh dấu progress | D27: Đủ dữ liệu, audio fallback; progress content_type=kana | E27: Kana seed exists | F27: Pending | G27: 46229 | H27: Codex QA | I27: Pending | L27: Pending | O27: Test Data: Hiragana/Katakana Priority: P1 Type: Functional, UI ROUND 1 ACTUAL RESULT (26 Jul 2026): PENDING — Frontend unit tests, lint, and production build passed, but no Playwright/Cypress browser runner is configured for this end-to-end UI scenario.
A28: Scenario: Vocabulary
A29: STU-012 | B29: [Student] Home/topics/list | C29: 1. Mở vocab 2. đổi level/topic/search/page | D29: Filter/pagination đúng; Unicode search; empty/loading/error đúng | E29: Published vocab | F29: Pending | G29: 46229 | H29: Codex QA | I29: Pending | L29: Pending | O29: Test Data: JP query, N5 Priority: P0 Type: Functional, UI ROUND 1 ACTUAL RESULT (26 Jul 2026): PENDING — Frontend unit tests, lint, and production build passed, but no Playwright/Cypress browser runner is configured for this end-to-end UI scenario.
A30: STU-013 | B30: [Student] Invalid filters | C30: level lạ, page âm, size 0/rất lớn, SQL/XSS | D30: 400 hoặc safe defaults; không injection/XSS | E30: Logged in | F30: Pending | G30: 46229 | H30: Codex QA | I30: Pending | L30: Pending | O30: Test Data: invalid set Priority: P1 Type: Negative, Security ROUND 1 ACTUAL RESULT (26 Jul 2026): PENDING — No automated test directly covers every step and expected result of this System Test. Backend 120/120 and frontend 18/18 automated tests passed, but manual/full-stack execution is still required.
A31: Scenario: Grammar
A32: STU-014 | B32: [Student] List/detail | C32: 1. Mở `/grammar` 2. filter 3. detail | D32: Chỉ published; dữ liệu/Unicode đúng; 404 unknown | E32: Published grammar | F32: Pending | G32: 46229 | H32: Codex QA | I32: Pending | L32: Pending | O32: Test Data: N5 Priority: P1 Type: Functional ROUND 1 ACTUAL RESULT (26 Jul 2026): PENDING — No automated test directly covers every step and expected result of this System Test. Backend 120/120 and frontend 18/18 automated tests passed, but manual/full-stack execution is still required.
A33: Scenario: Kanji
A34: STU-015 | B34: [Student] List/detail | C34: 1. Mở list 2. pagination 3. detail | D34: Meaning/readings/stroke info đúng; filter/boundary đúng | E34: Published Kanji | F34: Pending | G34: 46229 | H34: Codex QA | I34: Pending | L34: Pending | O34: Test Data: N5 Kanji Priority: P0 Type: Functional ROUND 1 ACTUAL RESULT (26 Jul 2026): PENDING — No automated test directly covers every step and expected result of this System Test. Backend 120/120 and frontend 18/18 automated tests passed, but manual/full-stack execution is still required.
A35: Scenario: Kanji Writing
A36: STU-016 | B36: [Student] Evaluate stroke | C36: 1. Vẽ path đúng/sai/ngắn 2. submit stroke | D36: DTW score/quality/direction hợp lệ; path quá ngắn xử lý an toàn | E36: Detail open | F36: Pending | G36: 46229 | H36: Codex QA | I36: Pending | L36: Pending | O36: Test Data: valid + short + extreme coords Priority: P0 Type: Functional, Boundary ROUND 1 ACTUAL RESULT (26 Jul 2026): PENDING — No automated test directly covers every step and expected result of this System Test. Backend 120/120 and frontend 18/18 automated tests passed, but manual/full-stack execution is still required.
A37: STU-017 | B37: [Student] Save attempt | C37: Submit full attempt hai lần | D37: Row lưu đúng Student, score/quality; JSON hợp lệ; duplicate behavior xác định | E37: Các nét đã đánh giá | F37: Pending | G37: 46229 | H37: Codex QA | I37: Pending | L37: Pending | O37: Test Data: stroke JSON Priority: P1 Type: Integration, Database ROUND 1 ACTUAL RESULT (26 Jul 2026): PENDING — No automated test directly covers every step and expected result of this System Test. Backend 120/120 and frontend 18/18 automated tests passed, but manual/full-stack execution is still required.
A38: Scenario: Assessment
A39: STU-018 | B39: [Student] List quiz | C39: 1. Mở `/quiz` 2. filter/list | D39: Chỉ quiz published/not deleted; empty/error state đúng | E39: Published quiz exists | F39: Pending | G39: 46229 | H39: Codex QA | I39: Pending | L39: Pending | O39: Test Data: N5 Priority: P0 Type: Smoke ROUND 1 ACTUAL RESULT (26 Jul 2026): PARTIALLY EXECUTED — AssessmentControllerIntegrationTest passed published quiz listing and unauthenticated rejection; UI empty/error states remain.
A40: STU-019 | B40: [Student] Start quiz | C40: Start một quiz | D40: Tạo attempt `in_progress`; câu hỏi không lộ đáp án đúng | E40: Eligible Student | F40: Pending | G40: 46229 | H40: Codex QA | I40: Pending | L40: Pending | O40: Test Data: assessment ID Priority: P0 Type: Functional, Security ROUND 1 ACTUAL RESULT (26 Jul 2026): PARTIALLY EXECUTED — Assessment and Mock Exam integration tests passed start behavior and answer-hiding checks; the complete quiz DB/UI scenario remains.
A41: STU-020 | B41: [Student] Submit/score | C41: Submit mixed answers | D41: Backend tính score; attempt submitted; answer rows đúng; score 0..max | E41: In-progress attempt | F41: Pending | G41: 46229 | H41: Codex QA | I41: Pending | L41: Pending | O41: Test Data: correct/wrong/blank Priority: P0 Type: Functional, Database ROUND 1 ACTUAL RESULT (26 Jul 2026): PARTIALLY EXECUTED — Assessment integration and MockExam service tests passed server-side scoring and score invariants; answer-row and UI verification remain.
A42: STU-021 | B42: [Student] Invalid/replay/concurrent submit | C42: Submit lại, hai tab, ID người khác | D42: Chỉ một transition; không double attempt mutation; 403/409/422 phù hợp | E42: Attempt submitted/expired/foreign | F42: Pending | G42: 46229 | H42: Codex QA | I42: Pending | L42: Pending | O42: Test Data: answer set Priority: P0 Type: Concurrent, Security ROUND 1 ACTUAL RESULT (26 Jul 2026): PARTIALLY EXECUTED — MockExam integration tests passed replay rejection; simultaneous-tab and foreign-attempt coverage remain.
...

Sheet Staff
A2: Workflow | B2: Staff | R2: Passed
A3: Test requirement | B3: Staff dashboard, authoring, support, broadcast and grading | R3: Failed
A4: Number of TCs | B4: =COUNTA(A12:A1000) | R4: Pending
A5: Testing Round | B5: Passed | C5: Failed | D5: Pending | E5: N/A | R5: N/A
A6: Round 1 | B6: =COUNTIF($F$12:$F$1000,"Passed") | C6: =COUNTIF($F$12:$F$1000,"Failed") | D6: =COUNTIF($F$12:$F$1000,"Pending") | E6: =COUNTIF($F$12:$F$1000,"N/A")
A7: Round 2 | B7: =COUNTIF($I$12:$I$1000,"Passed") | C7: =COUNTIF($I$12:$I$1000,"Failed") | D7: =COUNTIF($I$12:$I$1000,"Pending") | E7: =COUNTIF($I$12:$I$1000,"N/A")
A8: Round 3 | B8: =COUNTIF($L$12:$L$1000,"Passed") | C8: =COUNTIF($L$12:$L$1000,"Failed") | D8: =COUNTIF($L$12:$L$1000,"Pending") | E8: =COUNTIF($L$12:$L$1000,"N/A")
A10: Test Case ID | B10: Test Case Description | C10: Test Case Procedure | D10: Expected Results | E10: Pre-conditions | F10: Round 1 | G10: Test date | H10: Tester | I10: Round 2 | J10: Test date | K10: Tester | L10: Round 3 | M10: Test date | N10: Tester | O10: Note
A11: Scenario: Dashboard
A12: STF-001 | B12: [Staff] Metrics/tasks | C12: 1. Mở `/staff` 2. compare API/DB | D12: KPI/task list chính xác; no Admin/Manager action | E12: Staff logged in | F12: Pending | G12: 46229 | H12: Codex QA | I12: Pending | L12: Pending | O12: Test Data: seeded content/tickets Priority: P1 Type: Smoke, Database ROUND 1 ACTUAL RESULT (26 Jul 2026): PENDING — No automated test directly covers every step and expected result of this System Test. Backend 120/120 and frontend 18/18 automated tests passed, but manual/full-stack execution is still required.
A13: Scenario: Students
A14: STF-002 | B14: [Staff] List/filter/progress | C14: 1. Search/filter/page 2. open progress | D14: Correct data; no password/token; pagination đúng | E14: Students exist | F14: Pending | G14: 46229 | H14: Codex QA | I14: Pending | L14: Pending | O14: Test Data: status/level/query Priority: P1 Type: Functional ROUND 1 ACTUAL RESULT (26 Jul 2026): PENDING — No automated test directly covers every step and expected result of this System Test. Backend 120/120 and frontend 18/18 automated tests passed, but manual/full-stack execution is still required.
A15: STF-003 | B15: [Staff] Suspend/activate | C15: 1. Suspend with reason 2. activate 3. concurrent change | D15: State valid; audit row; UI refresh; conflict handled | E15: Target active/suspended | F15: Pending | G15: 46229 | H15: Codex QA | I15: Pending | L15: Pending | O15: Test Data: reason boundaries Priority: P0 Type: Functional, Concurrent ROUND 1 ACTUAL RESULT (26 Jul 2026): PENDING — No automated test directly covers every step and expected result of this System Test. Backend 120/120 and frontend 18/18 automated tests passed, but manual/full-stack execution is still required.
A16: Scenario: Questions
A17: STF-004 | B17: [Staff] Create positive | C17: Create MC/fill/true-false | D17: Draft created_by Staff; correct fields; UI row appears | E17: Staff logged in | F17: Pending | G17: 46229 | H17: Codex QA | I17: Pending | L17: Pending | O17: Test Data: valid per type Priority: P0 Type: Functional ROUND 1 ACTUAL RESULT (26 Jul 2026): PENDING — No automated test directly covers every step and expected result of this System Test. Backend 120/120 and frontend 18/18 automated tests passed, but manual/full-stack execution is still required.
A18: STF-005 | B18: [Staff] Validation/boundary | C18: 1. Missing correct answer/options 2. bad level/type 3. long text/XSS | D18: 400; no partial row; safe rendering | E18: None | F18: Pending | G18: 46229 | H18: Codex QA | I18: Pending | L18: Pending | O18: Test Data: invalid set Priority: P0 Type: Negative, Security ROUND 1 ACTUAL RESULT (26 Jul 2026): PENDING — No automated test directly covers every step and expected result of this System Test. Backend 120/120 and frontend 18/18 automated tests passed, but manual/full-stack execution is still required.
A19: STF-006 | B19: [Staff] List/detail/update | C19: 1. Filter 2. detail 3. update editable content | D19: Correct list; update timestamp/content; ownership/state rules enforced | E19: Own/other draft exists | F19: Pending | G19: 46229 | H19: Codex QA | I19: Pending | L19: Pending | O19: Test Data: valid update Priority: P1 Type: Functional ROUND 1 ACTUAL RESULT (26 Jul 2026): PENDING — No automated test directly covers every step and expected result of this System Test. Backend 120/120 and frontend 18/18 automated tests passed, but manual/full-stack execution is still required.
A20: STF-007 | B20: [Staff] Submit review/locked | C20: 1. Submit 2. edit pending/published/attempt-used question | D20: Valid → pending; incomplete blocked; immutable result integrity | E20: Complete/incomplete/used question | F20: Pending | G20: 46229 | H20: Codex QA | I20: Pending | L20: Pending | O20: Test Data: fixtures Priority: P0 Type: Workflow ROUND 1 ACTUAL RESULT (26 Jul 2026): PENDING — No automated test directly covers every step and expected result of this System Test. Backend 120/120 and frontend 18/18 automated tests passed, but manual/full-stack execution is still required.
A21: Scenario: Grammar
A22: STF-008 | B22: [Staff] CRUD/submit | C22: Create, list, detail, update, submit | D22: Draft→pending; creator set; validation/audit as expected | E22: Staff logged in | F22: Pending | G22: 46229 | H22: Codex QA | I22: Pending | L22: Pending | O22: Test Data: valid grammar Priority: P1 Type: Functional ROUND 1 ACTUAL RESULT (26 Jul 2026): PENDING — No automated test directly covers every step and expected result of this System Test. Backend 120/120 and frontend 18/18 automated tests passed, but manual/full-stack execution is still required.
A23: Scenario: Vocabulary Topic
A24: STF-009 | B24: [Staff] List/create unique | C24: 1. Create topic 2. duplicate slug/title 3. boundary order | D24: Unique constraints surfaced as 409/validation; no 500 | E24: Staff logged in | F24: Pending | G24: 46229 | H24: Codex QA | I24: Pending | L24: Pending | O24: Test Data: N5 topic Priority: P1 Type: Functional, Database ROUND 1 ACTUAL RESULT (26 Jul 2026): PARTIALLY EXECUTED — VocabularyTopicService tests passed slug generation and selected delete/restore rules; full create/list/unique API/UI flow remains.
A25: Scenario: Learning Content
A26: STF-010 | B26: [Staff] Lesson update | C26: 1. List/filter 2. update text/media/status | D26: Fields update; cannot directly publish as Staff; validation works | E26: Own lesson draft | F26: Pending | G26: 46229 | H26: Codex QA | I26: Pending | L26: Pending | O26: Test Data: valid/invalid Priority: P0 Type: Permission ROUND 1 ACTUAL RESULT (26 Jul 2026): PENDING — No automated test directly covers every step and expected result of this System Test. Backend 120/120 and frontend 18/18 automated tests passed, but manual/full-stack execution is still required.
A27: STF-011 | B27: [Staff] Vocabulary CRUD | C27: Create/list/detail/update/submit review | D27: FK topic valid; draft→pending; Unicode stored utf8mb4 | E27: Topic exists | F27: Pending | G27: 46229 | H27: Codex QA | I27: Pending | L27: Pending | O27: Test Data: JP vocab Priority: P0 Type: Functional, Database ROUND 1 ACTUAL RESULT (26 Jul 2026): PARTIALLY EXECUTED — Vocabulary topic delete/restore tests passed selected database state rules; complete vocabulary CRUD/Unicode workflow remains.
A28: STF-012 | B28: [Staff] Kanji CRUD | C28: Create/list/detail/update/submit | D28: Unique character enforced; state/creator correct | E28: Staff logged in | F28: Pending | G28: 46229 | H28: Codex QA | I28: Pending | L28: Pending | O28: Test Data: Kanji duplicate/valid Priority: P0 Type: Functional ROUND 1 ACTUAL RESULT (26 Jul 2026): PENDING — No automated test directly covers every step and expected result of this System Test. Backend 120/120 and frontend 18/18 automated tests passed, but manual/full-stack execution is still required.
A29: Scenario: Speaking Authoring
A30: STF-013 | B30: [Staff] Create/update/detail | C30: 1. Create speaking lesson/questions 2. edit 3. get own | D30: Lesson/questions transactionally saved; order correct | E30: Staff logged in | F30: Passed | G30: 46229 | H30: Codex QA | I30: Pending | L30: Pending | O30: Test Data: valid/boundary Priority: P1 Type: Functional ROUND 1 ACTUAL RESULT (26 Jul 2026): PASSED — SpeakingAuthoringServiceTest passed create, update, detail, ordering, validation, and atomic replacement checks.
A31: Scenario: Quiz
A32: STF-014 | B32: [Staff] Create/list/detail/update | C32: CRUD quiz | D32: Assessment type=quiz; validation; UI state correct | E32: Questions exist | F32: Pending | G32: 46229 | H32: Codex QA | I32: Pending | L32: Pending | O32: Test Data: score/duration/level boundaries Priority: P0 Type: Functional ROUND 1 ACTUAL RESULT (26 Jul 2026): PENDING — No automated test directly covers every step and expected result of this System Test. Backend 120/120 and frontend 18/18 automated tests passed, but manual/full-stack execution is still required.
A33: STF-015 | B33: [Staff] Assign questions | C33: Assign/reorder/duplicate/foreign question | D33: Unique prevents duplicate; score/display order correct; atomic failure | E33: Draft quiz | F33: Pending | G33: 46229 | H33: Codex QA | I33: Pending | L33: Pending | O33: Test Data: assignments Priority: P0 Type: Integration, Database ROUND 1 ACTUAL RESULT (26 Jul 2026): PENDING — No automated test directly covers every step and expected result of this System Test. Backend 120/120 and frontend 18/18 automated tests passed, but manual/full-stack execution is still required.
A34: Scenario: Exam
A35: STF-016 | B35: [Staff] Create/list/detail/update | C35: CRUD exam | D35: Assessment type=exam; filters and fields correct | E35: Questions exist | F35: Pending | G35: 46229 | H35: Codex QA | I35: Pending | L35: Pending | O35: Test Data: valid exam Priority: P0 Type: Functional ROUND 1 ACTUAL RESULT (26 Jul 2026): PENDING — No automated test directly covers every step and expected result of this System Test. Backend 120/120 and frontend 18/18 automated tests passed, but manual/full-stack execution is still required.
A36: STF-017 | B36: [Staff] Assign/submit review | C36: 1. Assign sections 2. submit complete/incomplete | D36: Complete → pending; invalid structure blocked; no partial update | E36: Draft exam | F36: Pending | G36: 46229 | H36: Codex QA | I36: Pending | L36: Pending | O36: Test Data: assignment set Priority: P0 Type: Workflow ROUND 1 ACTUAL RESULT (26 Jul 2026): PARTIALLY EXECUTED — StaffExamServiceSubmitReviewTest passed rejection of an empty exam; valid complete submission and atomic assignment remain.
A37: Scenario: Review Feedback
A38: STF-018 | B38: [Staff] View feedback | C38: Open feedback modal/API | D38: Latest relevant feedback shown only to creator/allowed Staff | E38: Content rejected/change requested | F38: Pending | G38: 46229 | H38: Codex QA | I38: Pending | L38: Pending | O38: Test Data: content type/id Priority: P1 Type: Permission ROUND 1 ACTUAL RESULT (26 Jul 2026): PENDING — No automated test directly covers every step and expected result of this System Test. Backend 120/120 and frontend 18/18 automated tests passed, but manual/full-stack execution is still required.
A39: Scenario: Tickets
A40: STF-019 | B40: [Staff] List/detail/reply/close | C40: Process ticket | D40: assigned→in_progress→resolved; notification; audit | E40: Ticket assigned to Staff | F40: Pending | G40: 46229 | H40: Codex QA | I40: Pending | L40: Pending | O40: Test Data: reply/attachment Priority: P0 Type: Workflow ROUND 1 ACTUAL RESULT (26 Jul 2026): PARTIALLY EXECUTED — SupportTicketServiceTest passed assignee/manager reply and lifecycle rules; full Staff UI, attachment, notification, and audit checks remain.
A41: STF-020 | B41: [Staff] Unauthorized ticket | C41: Direct detail/reply/close | D41: Staff thường bị 403; Manager exception tested separately | E41: Ticket assigned other Staff | F41: Pending | G41: 46229 | H41: Codex QA | I41: Pending | L41: Pending | O41: Test Data: ticket ID Priority: P0 Type: Permission ROUND 1 ACTUAL RESULT (26 Jul 2026): PARTIALLY EXECUTED — SupportTicketServiceTest passed unauthorized Staff reply rejection; direct detail/close API and UI checks remain.
A42: Scenario: Broadcast
...

Sheet Manager
A2: Workflow | B2: Manager | R2: Passed
A3: Test requirement | B3: StaffManager review, publish, restore and coordination | R3: Failed
A4: Number of TCs | B4: =COUNTA(A12:A1000) | R4: Pending
A5: Testing Round | B5: Passed | C5: Failed | D5: Pending | E5: N/A | R5: N/A
A6: Round 1 | B6: =COUNTIF($F$12:$F$1000,"Passed") | C6: =COUNTIF($F$12:$F$1000,"Failed") | D6: =COUNTIF($F$12:$F$1000,"Pending") | E6: =COUNTIF($F$12:$F$1000,"N/A")
A7: Round 2 | B7: =COUNTIF($I$12:$I$1000,"Passed") | C7: =COUNTIF($I$12:$I$1000,"Failed") | D7: =COUNTIF($I$12:$I$1000,"Pending") | E7: =COUNTIF($I$12:$I$1000,"N/A")
A8: Round 3 | B8: =COUNTIF($L$12:$L$1000,"Passed") | C8: =COUNTIF($L$12:$L$1000,"Failed") | D8: =COUNTIF($L$12:$L$1000,"Pending") | E8: =COUNTIF($L$12:$L$1000,"N/A")
A10: Test Case ID | B10: Test Case Description | C10: Test Case Procedure | D10: Expected Results | E10: Pre-conditions | F10: Round 1 | G10: Test date | H10: Tester | I10: Round 2 | J10: Test date | K10: Tester | L10: Round 3 | M10: Test date | N10: Tester | O10: Note
A11: Scenario: Dashboard
A12: MGR-001 | B12: [Manager] Navigation/summary | C12: 1. Mở `/manager` 2. inspect cards/menu | D12: Manager dashboard loads; Staff capabilities preserved where linked | E12: Manager logged in | F12: Pending | G12: 46229 | H12: Codex QA | I12: Pending | L12: Pending | O12: Test Data: pending content/tickets Priority: P1 Type: Smoke ROUND 1 ACTUAL RESULT (26 Jul 2026): PENDING — No automated test directly covers every step and expected result of this System Test. Backend 120/120 and frontend 18/18 automated tests passed, but manual/full-stack execution is still required.
A13: Scenario: Review
A14: MGR-002 | B14: [Manager] Queue/filter/page | C14: Filter type/level/page | D14: Queue complete; correct creator/snapshot metadata; no deleted item | E14: Pending all content types | F14: Pending | G14: 46229 | H14: Codex QA | I14: Pending | L14: Pending | O14: Test Data: lesson/grammar/vocab/kanji/question/assessment Priority: P0 Type: Functional ROUND 1 ACTUAL RESULT (26 Jul 2026): PENDING — No automated test directly covers every step and expected result of this System Test. Backend 120/120 and frontend 18/18 automated tests passed, but manual/full-stack execution is still required.
A15: MGR-003 | B15: [Manager] Detail | C15: Open detail directly/UI | D15: Correct handler/type; snapshot and creator shown; unknown/type mismatch 404/400 | E15: Pending item | F15: Pending | G15: 46229 | H15: Codex QA | I15: Pending | L15: Pending | O15: Test Data: content IDs Priority: P0 Type: Functional ROUND 1 ACTUAL RESULT (26 Jul 2026): PENDING — No automated test directly covers every step and expected result of this System Test. Backend 120/120 and frontend 18/18 automated tests passed, but manual/full-stack execution is still required.
A16: MGR-004 | B16: [Manager] Approve | C16: Approve | D16: pending→published; approver/published_at set; audit row; Student can see | E16: Other Staff pending content | F16: Pending | G16: 46229 | H16: Codex QA | I16: Pending | L16: Pending | O16: Test Data: valid item Priority: P0 Type: Workflow, Database ROUND 1 ACTUAL RESULT (26 Jul 2026): PARTIALLY EXECUTED — AssessmentContentHandlerTest passed publish approval rules for assessments; all content types, audit, and Student visibility remain.
A17: MGR-005 | B17: [Manager] Reject/request changes | C17: Reject/change without and with feedback | D17: Feedback required; valid transition; Staff can read feedback; audit | E17: Pending content | F17: Pending | G17: 46229 | H17: Codex QA | I17: Pending | L17: Pending | O17: Test Data: empty/valid feedback Priority: P0 Type: Negative, Workflow ROUND 1 ACTUAL RESULT (26 Jul 2026): PENDING — No automated test directly covers every step and expected result of this System Test. Backend 120/120 and frontend 18/18 automated tests passed, but manual/full-stack execution is still required.
A18: MGR-006 | B18: [Manager] Self-review prohibition | C18: Approve/reject own item via UI/API | D18: 403/422; status unchanged; event logged safely | E18: Manager-created content pending | F18: Pending | G18: 46229 | H18: Codex QA | I18: Pending | L18: Pending | O18: Test Data: own ID Priority: P0 Type: Permission ROUND 1 ACTUAL RESULT (26 Jul 2026): PENDING — No automated test directly covers every step and expected result of this System Test. Backend 120/120 and frontend 18/18 automated tests passed, but manual/full-stack execution is still required.
A19: MGR-007 | B19: [Manager] Concurrent reviewers | C19: Both approve/reject same version simultaneously | D19: Exactly one succeeds; other gets conflict/latest state; one final transition | E19: Two Managers | F19: Pending | G19: 46229 | H19: Codex QA | I19: Pending | L19: Pending | O19: Test Data: same item Priority: P0 Type: Concurrent ROUND 1 ACTUAL RESULT (26 Jul 2026): PENDING — No automated test directly covers every step and expected result of this System Test. Backend 120/120 and frontend 18/18 automated tests passed, but manual/full-stack execution is still required.
A20: Scenario: Publish
A21: MGR-008 | B21: [Manager] List/detail/filter | C21: 1. Open pipeline 2. filter/detail | D21: Correct content/state; Staff normal cannot access | E21: Published/archived items | F21: Pending | G21: 46229 | H21: Codex QA | I21: Pending | L21: Pending | O21: Test Data: type/level Priority: P0 Type: Functional, Permission ROUND 1 ACTUAL RESULT (26 Jul 2026): PENDING — No automated test directly covers every step and expected result of this System Test. Backend 120/120 and frontend 18/18 automated tests passed, but manual/full-stack execution is still required.
A22: MGR-009 | B22: [Manager] State transitions | C22: Publish, unpublish/archive, restore | D22: Only allowed transitions; reason/audit stored; Student visibility updates | E22: Approved/published/archived | F22: Pending | G22: 46229 | H22: Codex QA | I22: Pending | L22: Pending | O22: Test Data: reason boundary Priority: P0 Type: Workflow ROUND 1 ACTUAL RESULT (26 Jul 2026): PENDING — No automated test directly covers every step and expected result of this System Test. Backend 120/120 and frontend 18/18 automated tests passed, but manual/full-stack execution is still required.
A23: MGR-010 | B23: [Manager] Invalid transition | C23: 1. Direct status calls 2. missing reason | D23: 409/422; no state corruption; dependency warning handled | E23: Draft/deleted/in-use content | F23: Pending | G23: 46229 | H23: Codex QA | I23: Pending | L23: Pending | O23: Test Data: invalid transitions Priority: P0 Type: Negative ROUND 1 ACTUAL RESULT (26 Jul 2026): PENDING — No automated test directly covers every step and expected result of this System Test. Backend 120/120 and frontend 18/18 automated tests passed, but manual/full-stack execution is still required.
A24: Scenario: Trash
A25: MGR-011 | B25: [Manager] List/restore | C25: 1. Filter type 2. restore once/twice/concurrently | D25: Restored correctly; repeat idempotent/conflict; audit | E25: Soft-deleted content | F25: Pending | G25: 46229 | H25: Codex QA | I25: Pending | L25: Pending | O25: Test Data: IDs Priority: P1 Type: Functional, Concurrent ROUND 1 ACTUAL RESULT (26 Jul 2026): PARTIALLY EXECUTED — ManagerDeletedContentServiceTest and VocabularyTopicService tests passed list/restore authorization and selected transitions; concurrency remains.
A26: Scenario: Tickets
A27: MGR-012 | B27: [Manager] Assign | C27: 1. Load assignees 2. assign 3. reassign | D27: open→assigned; correct assignee; counts refresh; audit/notification | E27: Open ticket, Staff list | F27: Pending | G27: 46229 | H27: Codex QA | I27: Pending | L27: Pending | O27: Test Data: Staff IDs Priority: P0 Type: Workflow ROUND 1 ACTUAL RESULT (26 Jul 2026): PARTIALLY EXECUTED — SupportTicket tests passed assignment and Manager reply behavior; full UI/count/audit/notification verification remains.
A28: MGR-013 | B28: [Manager] Invalid assign | C28: Assign | D28: 400/404/409; status unchanged | E28: Suspended/nonexistent Staff; resolved ticket | F28: Pending | G28: 46229 | H28: Codex QA | I28: Pending | L28: Pending | O28: Test Data: invalid IDs Priority: P1 Type: Negative ROUND 1 ACTUAL RESULT (26 Jul 2026): PARTIALLY EXECUTED — SupportTicketAssignTest passed suspended-target rejection and missing-target handling; resolved-ticket handling remains.
A29: Scenario: Broadcast
A30: MGR-014 | B30: [Manager] Send all/schedule | C30: 1. Confirm “all” 2. send and schedule | D30: Confirmation required; accepted job; no duplicate click submission | E30: Manager logged in | F30: Pending | G30: 46229 | H30: Codex QA | I30: Pending | L30: Pending | O30: Test Data: channels/levels Priority: P1 Type: UI, Integration ROUND 1 ACTUAL RESULT (26 Jul 2026): PENDING — Frontend unit tests, lint, and production build passed, but no Playwright/Cypress browser runner is configured for this end-to-end UI scenario.
A31: Scenario: UI/Permission
A32: MGR-015 | B32: [Manager] Menus/direct API | C32: 1. Traverse manager menu 2. call Admin APIs 3. hidden actions | D32: Manager routes work; Admin 403; no Admin menu; Staff normal Manager API denied by service | E32: Manager logged in | F32: Pending | G32: 46229 | H32: Codex QA | I32: Pending | L32: Pending | O32: Test Data: routes/tokens Priority: P0 Type: Permission, Regression ROUND 1 ACTUAL RESULT (26 Jul 2026): PENDING — Frontend unit tests, lint, and production build passed, but no Playwright/Cypress browser runner is configured for this end-to-end UI scenario.

Sheet Admin
A2: Workflow | B2: Admin | R2: Passed
A3: Test requirement | B3: Admin dashboard, users, settings, audit and notification rules | R3: Failed
A4: Number of TCs | B4: =COUNTA(A12:A1000) | R4: Pending
A5: Testing Round | B5: Passed | C5: Failed | D5: Pending | E5: N/A | R5: N/A
A6: Round 1 | B6: =COUNTIF($F$12:$F$1000,"Passed") | C6: =COUNTIF($F$12:$F$1000,"Failed") | D6: =COUNTIF($F$12:$F$1000,"Pending") | E6: =COUNTIF($F$12:$F$1000,"N/A")
A7: Round 2 | B7: =COUNTIF($I$12:$I$1000,"Passed") | C7: =COUNTIF($I$12:$I$1000,"Failed") | D7: =COUNTIF($I$12:$I$1000,"Pending") | E7: =COUNTIF($I$12:$I$1000,"N/A")
A8: Round 3 | B8: =COUNTIF($L$12:$L$1000,"Passed") | C8: =COUNTIF($L$12:$L$1000,"Failed") | D8: =COUNTIF($L$12:$L$1000,"Pending") | E8: =COUNTIF($L$12:$L$1000,"N/A")
A10: Test Case ID | B10: Test Case Description | C10: Test Case Procedure | D10: Expected Results | E10: Pre-conditions | F10: Round 1 | G10: Test date | H10: Tester | I10: Round 2 | J10: Test date | K10: Tester | L10: Round 3 | M10: Test date | N10: Tester | O10: Note
A11: Scenario: Dashboard
A12: ADM-001 | B12: [Admin] KPI | C12: 1. Mở `/admin` 2. compare summary with SQL | D12: Accurate KPI; no sensitive password/token; error state works | E12: Admin logged in; seeded DB | F12: Pending | G12: 46229 | H12: Codex QA | I12: Pending | L12: Pending | O12: Test Data: users/attempts/content Priority: P0 Type: Smoke, Database ROUND 1 ACTUAL RESULT (26 Jul 2026): PENDING — No automated test directly covers every step and expected result of this System Test. Backend 120/120 and frontend 18/18 automated tests passed, but manual/full-stack execution is still required.
A13: Scenario: Audit
A14: ADM-002 | B14: [Admin] List/filter/page | C14: 1. Mở `/admin/reports` 2. filter action/target/page | D14: UI/API/DB consistent; actor/action/time displayed; no export button | E14: Audit rows exist | F14: Pending | G14: 46229 | H14: Codex QA | I14: Pending | L14: Pending | O14: Test Data: action set Priority: P0 Type: Functional ROUND 1 ACTUAL RESULT (26 Jul 2026): PENDING — No automated test directly covers every step and expected result of this System Test. Backend 120/120 and frontend 18/18 automated tests passed, but manual/full-stack execution is still required.
A15: Scenario: Users
A16: ADM-003 | B16: [Admin] List/filter/detail | C16: 1. Filter type/status/level/role/search 2. detail | D16: Pagination/filters correct; deleted handled; secrets hidden | E16: Mixed users | F16: Pending | G16: 46229 | H16: Codex QA | I16: Pending | L16: Pending | O16: Test Data: query set Priority: P0 Type: Functional ROUND 1 ACTUAL RESULT (26 Jul 2026): PENDING — No automated test directly covers every step and expected result of this System Test. Backend 120/120 and frontend 18/18 automated tests passed, but manual/full-stack execution is still required.
A17: ADM-004 | B17: [Admin] Create Staff | C17: 1. Create Staff/Manager 2. duplicate/invalid email/role | D17: Correct role/status/temp setup; unique email; audit/email | E17: Admin logged in | F17: Pending | G17: 46229 | H17: Codex QA | I17: Pending | L17: Pending | O17: Test Data: valid/invalid Priority: P0 Type: Functional ROUND 1 ACTUAL RESULT (26 Jul 2026): PARTIALLY EXECUTED — AdminUserServiceTest passed Staff creation, duplicate rejection, and invitation dispatch; full browser and database verification remain.
A18: ADM-005 | B18: [Admin] Update Student/Staff | C18: 1. Edit allowed fields 2. invalid/overlong/XSS | D18: Only allowed fields update; role not changed by generic update; safe output | E18: Targets exist | F18: Pending | G18: 46229 | H18: Codex QA | I18: Pending | L18: Pending | O18: Test Data: payload set Priority: P1 Type: Security ROUND 1 ACTUAL RESULT (26 Jul 2026): PENDING — No automated test directly covers every step and expected result of this System Test. Backend 120/120 and frontend 18/18 automated tests passed, but manual/full-stack execution is still required.
A19: ADM-006 | B19: [Admin] Suspend/activate | C19: 1. Suspend reason min/max 2. activate 3. self-target cases | D19: State transition valid; sessions handled by policy; audit | E19: Active/suspended target | F19: Pending | G19: 46229 | H19: Codex QA | I19: Pending | L19: Pending | O19: Test Data: boundary reason Priority: P0 Type: Workflow ROUND 1 ACTUAL RESULT (26 Jul 2026): PARTIALLY EXECUTED — AdminUserServiceTest passed suspend/activate state rules; UI refresh, audit, and concurrent changes remain.
A20: ADM-007 | B20: [Admin] Reset password | C20: 1. Reset Student 2. inspect response/email | D20: No plaintext persisted/logged; secure reset flow; audit | E20: Target exists | F20: Pending | G20: 46229 | H20: Codex QA | I20: Pending | L20: Pending | O20: Test Data: user ID Priority: P0 Type: Security ROUND 1 ACTUAL RESULT (26 Jul 2026): PENDING — No automated test directly covers every step and expected result of this System Test. Backend 120/120 and frontend 18/18 automated tests passed, but manual/full-stack execution is still required.
A21: Scenario: Staff Reset
A22: ADM-008 | B22: [Admin] Request lifecycle | C22: 1. List 2. issue temp password 3. repeat/expired | D22: Completed once; Staff must change password; audit/email | E22: Pending Staff request | F22: Pending | G22: 46229 | H22: Codex QA | I22: Pending | L22: Pending | O22: Test Data: request IDs Priority: P0 Type: Workflow ROUND 1 ACTUAL RESULT (26 Jul 2026): PENDING — No automated test directly covers every step and expected result of this System Test. Backend 120/120 and frontend 18/18 automated tests passed, but manual/full-stack execution is still required.
A23: Scenario: Users
A24: ADM-009 | B24: [Admin] Soft delete/restore | C24: 1. Delete 2. login/direct API 3. restore | D24: status deleted; access blocked; related data retained; restore works; audit | E24: Target exists | F24: Pending | G24: 46229 | H24: Codex QA | I24: Pending | L24: Pending | O24: Test Data: Student/Staff Priority: P0 Type: Functional, Database ROUND 1 ACTUAL RESULT (26 Jul 2026): PARTIALLY EXECUTED — AdminUserServiceTest passed soft delete/restore and invalid transition rules; full UI and audit verification remain.
A25: ADM-010 | B25: [Admin] Change Staff role | C25: 1. Promote/demote 2. concurrent changes 3. invalid role | D25: staff_role updated only valid values; permissions change after new auth; audit | E25: Staff/Manager target | F25: Pending | G25: 46229 | H25: Codex QA | I25: Pending | L25: Pending | O25: Test Data: roles Priority: P0 Type: Permission, Concurrent ROUND 1 ACTUAL RESULT (26 Jul 2026): PARTIALLY EXECUTED — AdminUserServiceChangeRoleTest passed suspended-Staff rejection; valid role changes and complete audit/UI coverage remain.
A26: Scenario: Settings
A27: ADM-011 | B27: [Admin] Read group | C27: 1. Open settings 2. fetch allowed/unknown group | D27: Editable metadata correct; unknown group handled; secret values masked if applicable | E27: Settings seeded | F27: Pending | G27: 46229 | H27: Codex QA | I27: Pending | L27: Pending | O27: Test Data: system/email/... Priority: P1 Type: Functional ROUND 1 ACTUAL RESULT (26 Jul 2026): PENDING — The relevant external provider/file-delivery workflow was not available as a complete System Test environment. Mocked automated checks passed where present.
A28: ADM-012 | B28: [Admin] Update one/batch | C28: 1. Update string/int/bool/time 2. invalid type 3. batch partial error | D28: Validation by type; batch atomic; updated_by/time set; audit | E28: Admin logged in | F28: Pending | G28: 46229 | H28: Codex QA | I28: Pending | L28: Pending | O28: Test Data: boundary values Priority: P0 Type: Integration, Database ROUND 1 ACTUAL RESULT (26 Jul 2026): PENDING — No automated test directly covers every step and expected result of this System Test. Backend 120/120 and frontend 18/18 automated tests passed, but manual/full-stack execution is still required.
